2024-01-10 15:25:13,254 - INFO - Planner initialized successfully
2024-01-10 15:25:13,304 - INFO - CodeInterpreter initialized successfully.
2024-01-10 15:25:13,306 - INFO - Session 20240110-112513-bc3733d4 is initialized
2024-01-10 15:25:13,310 - INFO - Use back up engine: False
2024-01-10 15:26:18,345 - INFO - LLM output: {"response": [{"type": "init_plan", "content": "1. Import the specified Python modules from the provided file paths\n2. Analyze the question to identify variables of interest <interactively depends on 1>\n3. Locate relevant dataframes and variable assignment statements <sequentially depends on 2>\n4. Locate relevant columns or rows in the dataframes <sequentially depends on 3>\n5. Locate relevant values in the dataframe or variable assignment statements <sequentially depends on 4>\n6. Generate a response with a detailed explanation and reference to the source document and page number <sequentially depends on 5>"}, {"type": "plan", "content": "1. Import the specified Python modules from the provided file paths\n2. Analyze the question to identify variables of interest\n3. Locate relevant dataframes and variable assignment statements\n4. Locate relevant columns or rows in the dataframes\n5. Locate relevant values in the dataframe or variable assignment statements\n6. Generate a response with a detailed explanation and reference to the source document and page number"}, {"type": "current_plan_step", "content": "1. Import the specified Python modules from the provided file paths"}, {"type": "send_to", "content": "CodeInterpreter"}, {"type": "message", "content": "Please import the Python modules from the following file paths:\n- c:\\Users\\selhousseini\\Documents\\GitHub\\mm-doc-analysis-rag-ce\\doc_ingestion_adia_cases\\Trend.pdf\\tables\\page_49_table_0.py\n- c:\\Users\\selhousseini\\Documents\\GitHub\\mm-doc-analysis-rag-ce\\doc_ingestion_adia_cases\\Trend.pdf\\tables\\page_41_table_0.py"}]}
2024-01-10 15:26:18,351 - INFO - Planner talk to CodeInterpreter: Please import the Python modules from the following file paths:
- c:\Users\selhousseini\Documents\GitHub\mm-doc-analysis-rag-ce\doc_ingestion_adia_cases\Trend.pdf\tables\page_49_table_0.py
- c:\Users\selhousseini\Documents\GitHub\mm-doc-analysis-rag-ce\doc_ingestion_adia_cases\Trend.pdf\tables\page_41_table_0.py
2024-01-10 15:26:18,351 - INFO - Use back up engine: False
2024-01-10 15:26:41,209 - INFO - LLM output: {"response": [{"type": "python", "content": "# Import the Python files specified by the user\n%run c:\\Users\\selhousseini\\Documents\\GitHub\\mm-doc-analysis-rag-ce\\doc_ingestion_adia_cases\\Trend.pdf\\tables\\page_49_table_0.py\n%run c:\\Users\\selhousseini\\Documents\\GitHub\\mm-doc-analysis-rag-ce\\doc_ingestion_adia_cases\\Trend.pdf\\tables\\page_41_table_0.py"}]}
2024-01-10 15:26:41,211 - INFO - Code to be verified: # Import the Python files specified by the user
%run c:\Users\selhousseini\Documents\GitHub\mm-doc-analysis-rag-ce\doc_ingestion_adia_cases\Trend.pdf\tables\page_49_table_0.py
%run c:\Users\selhousseini\Documents\GitHub\mm-doc-analysis-rag-ce\doc_ingestion_adia_cases\Trend.pdf\tables\page_41_table_0.py
2024-01-10 15:26:41,211 - INFO - Code to be executed: # Import the Python files specified by the user
%run c:\Users\selhousseini\Documents\GitHub\mm-doc-analysis-rag-ce\doc_ingestion_adia_cases\Trend.pdf\tables\page_49_table_0.py
%run c:\Users\selhousseini\Documents\GitHub\mm-doc-analysis-rag-ce\doc_ingestion_adia_cases\Trend.pdf\tables\page_41_table_0.py
2024-01-10 15:26:52,014 - INFO - CodeInterpreter talk to CodeInterpreter: The following python code has been executed:
```python
# Import the Python files specified by the user
%run c:\Users\selhousseini\Documents\GitHub\mm-doc-analysis-rag-ce\doc_ingestion_adia_cases\Trend.pdf\tables\page_49_table_0.py
%run c:\Users\selhousseini\Documents\GitHub\mm-doc-analysis-rag-ce\doc_ingestion_adia_cases\Trend.pdf\tables\page_41_table_0.py
```


The execution of the generated python code above has failed

During execution, the following messages were logged:
Traceback (most recent call last):

  File c:\Users\amantara\AppData\Local\miniconda3\envs\adiaped\lib\site-packages\IPython\core\magics\execution.py:716 in run
    filename = file_finder(fpath)

  File c:\Users\amantara\AppData\Local\miniconda3\envs\adiaped\lib\site-packages\IPython\utils\path.py:90 in get_py_filename
    raise IOError("File `%r` not found." % name)

OSError: File `'c:\\Users\\selhousseini\\Documents\\GitHub\\mm-doc-analysis-rag-ce\\doc_ingestion_adia_cases\\Trend.pdf\\tables\\page_49_table_0.py'` not found.


The above exception was the direct cause of the following exception:

Traceback (most recent call last):

  Cell In[1], line 2
    get_ipython().run_line_magic('run', 'c:\\Users\\selhousseini\\Documents\\GitHub\\mm-doc-analysis-rag-ce\\doc_ingestion_adia_cases\\Trend.pdf\\tables\\page_49_table_0.py')

  File c:\Users\amantara\AppData\Local\miniconda3\envs\adiaped\lib\site-packages\IPython\core\interactiveshell.py:2456 in run_line_magic
    result = fn(*args, **k

2024-01-10 15:26:52,014 - INFO - Use back up engine: True
2024-01-10 15:27:33,635 - INFO - LLM output: {"response": [{"type": "thought", "content": "The error indicates that the file paths provided do not exist or are incorrect. This could be due to a variety of reasons such as a typo in the file path, the files being moved or deleted, or a permissions issue preventing access to the files."}, {"type": "thought", "content": "Since the error is related to the file path and not the code itself, ProgramApe cannot fix the problem by rewriting the code. The user needs to provide the correct file paths or ensure that the files exist at the specified locations."}, {"type": "text", "content": "The error you're encountering indicates that the files at the specified paths cannot be found. This could be due to incorrect file paths or the files not being present at those locations. Please verify the file paths and ensure that the files exist. Once you have the correct paths, you can provide them to me, and I will attempt to import the modules again."}]}
2024-01-10 15:27:33,636 - INFO - CodeInterpreter talk to Planner: The error you're encountering indicates that the files at the specified paths cannot be found. This could be due to incorrect file paths or the files not being present at those locations. Please verify the file paths and ensure that the files exist. Once you have the correct paths, you can provide them to me, and I will attempt to import the modules again.
2024-01-10 15:27:33,636 - INFO - Use back up engine: False
2024-01-10 15:28:14,177 - INFO - LLM output: {"response": [{"type": "init_plan", "content": "1. Import the specified Python modules from the provided file paths\n2. Analyze the question to identify variables of interest <interactively depends on 1>\n3. Locate relevant dataframes and variable assignment statements <sequentially depends on 2>\n4. Locate relevant columns or rows in the dataframes <sequentially depends on 3>\n5. Locate relevant values in the dataframe or variable assignment statements <sequentially depends on 4>\n6. Generate a response with a detailed explanation and reference to the source document and page number <sequentially depends on 5>"}, {"type": "plan", "content": "1. Confirm the correct file paths with the user\n2. Import the specified Python modules from the confirmed file paths\n3. Analyze the question to identify variables of interest\n4. Locate relevant dataframes and variable assignment statements\n5. Locate relevant columns or rows in the dataframes\n6. Locate relevant values in the dataframe or variable assignment statements\n7. Generate a response with a detailed explanation and reference to the source document and page number"}, {"type": "current_plan_step", "content": "1. Confirm the correct file paths with the user"}, {"type": "send_to", "content": "User"}, {"type": "message", "content": "It seems there was an issue with the file paths provided. Could you please confirm the correct paths to the Python modules you would like to import?"}]}
2024-01-10 15:28:14,181 - INFO - Planner talk to User: It seems there was an issue with the file paths provided. Could you please confirm the correct paths to the Python modules you would like to import?
2024-01-28 21:32:28,260 - INFO - Planner initialized successfully
2024-01-28 21:32:28,311 - INFO - CodeInterpreter initialized successfully.
2024-01-28 21:32:28,312 - INFO - Session 20240128-173228-273ddaae is initialized
2024-01-28 21:32:29,595 - INFO - Use back up engine: False
2024-01-28 21:32:56,851 - INFO - LLM output: {"response": [{"type": "init_plan", "content": "1. Analyze the user's request and identify the variables of interest for the business overview\n2. Locate the relevant dataframes and variable assignment statements for the company overview\n3. Extract key financial metrics such as EBITDA, margins, revenue, and CAGR\n4. Identify and analyze sales segmentation or revenue split data\n5. Detail the distribution network and number of outlets\n6. Integrate and compare datasets if both sales segmentation and revenue split data are available\n7. Provide a detailed summary of the company's business overview with a focus on the requested elements"}, {"type": "plan", "content": "1. Locate and print the variables of interest for the company overview\n2. Locate and print the relevant dataframes names, their columns, and all variable assignment statements\n3. Determine in which columns the variables of interest appear in the dataframes using str.contains method on all columns\n4. Provide a detailed summary of the company's business overview with a focus on the requested elements"}, {"type": "current_plan_step", "content": "1. Locate and print the variables of interest for the company overview"}, {"type": "send_to", "content": "CodeInterpreter"}, {"type": "message", "content": "Please locate and print the variables of interest for the company overview, including the relevant dataframes names, their columns, and all variable assignment statements related to the company's background, market entry, operational highlights, key financials, sales segmentation, revenue split, and distribution network."}]}
2024-01-28 21:32:56,879 - ERROR - Traceback (most recent call last):
  File "c:\Users\amantara\OneDrive - Microsoft\GBB\ADIA\PED\mm-doc-analysis-rag-ce\code\../TaskWeaver\taskweaver\session\session.py", line 132, in send_message
    post = _send_message(post.send_to, post)
  File "c:\Users\amantara\OneDrive - Microsoft\GBB\ADIA\PED\mm-doc-analysis-rag-ce\code\../TaskWeaver\taskweaver\session\session.py", line 104, in _send_message
    reply_post = self.planner.reply(
  File "c:\Users\amantara\OneDrive - Microsoft\GBB\ADIA\PED\mm-doc-analysis-rag-ce\code\../TaskWeaver\taskweaver\planner\planner.py", line 222, in reply
    response_post = self.planner_post_translator.raw_text_to_post(
  File "c:\Users\amantara\OneDrive - Microsoft\GBB\ADIA\PED\mm-doc-analysis-rag-ce\code\../TaskWeaver\taskweaver\role\translator.py", line 68, in raw_text_to_post
    event_handler(type_str, value)
TypeError: 'TWHandler' object is not callable

2024-02-02 09:50:25,930 - INFO - Planner initialized successfully
2024-02-02 09:50:26,022 - INFO - CodeInterpreter initialized successfully.
2024-02-02 09:50:26,025 - INFO - Session 20240202-055025-2ef8a4e8 is initialized
2024-02-02 09:50:27,039 - INFO - Use back up engine: False
2024-02-02 09:51:07,771 - INFO - LLM output: {"response": [{"type": "init_plan", "content": "1. Analyze the question and locate variables of interest and relevant dataframes\n2. Import the list of Python files specified by the user\n3. Identify and print relevant variables and their assignment statements\n4. Identify and print relevant dataframe names and their columns\n5. Extract information from Python codeblocks if necessary\n6. Generate the answer to the query with detailed calculation steps\n7. Provide a complete description of the calculation steps\n8. Create an Excel file with the data and calculation steps, save it, and print the full path"}, {"type": "plan", "content": "1. Analyze the question and locate variables of interest and relevant dataframes\n2. Import the list of Python files specified by the user\n3. Identify and print relevant variables and their assignment statements\n4. Identify and print relevant dataframe names and their columns\n5. Extract information from Python codeblocks if necessary\n6. Generate the answer to the query with detailed calculation steps\n7. Provide a complete description of the calculation steps\n8. Create an Excel file with the data and calculation steps, save it, and print the full path"}, {"type": "current_plan_step", "content": "1. Analyze the question and locate variables of interest and relevant dataframes"}, {"type": "send_to", "content": "CodeInterpreter"}, {"type": "message", "content": "Analyze the question 'give me business overview' and locate variables of interest and relevant dataframes from the provided code blocks."}]}
2024-02-02 09:51:07,849 - ERROR - Traceback (most recent call last):
  File "C:\Users\amantara\OneDrive - Microsoft\GBB\ADIA\PED\mm-doc-analysis-rag-ce\app\../Taskweaver\taskweaver\session\session.py", line 132, in send_message
    post = _send_message(post.send_to, post)
  File "C:\Users\amantara\OneDrive - Microsoft\GBB\ADIA\PED\mm-doc-analysis-rag-ce\app\../Taskweaver\taskweaver\session\session.py", line 104, in _send_message
    reply_post = self.planner.reply(
  File "C:\Users\amantara\OneDrive - Microsoft\GBB\ADIA\PED\mm-doc-analysis-rag-ce\app\../Taskweaver\taskweaver\planner\planner.py", line 222, in reply
    response_post = self.planner_post_translator.raw_text_to_post(
  File "C:\Users\amantara\OneDrive - Microsoft\GBB\ADIA\PED\mm-doc-analysis-rag-ce\app\../Taskweaver\taskweaver\role\translator.py", line 68, in raw_text_to_post
    event_handler(type_str, value)
TypeError: 'TWHandler' object is not callable

2024-02-02 18:14:17,555 - INFO - Planner initialized successfully
2024-02-02 18:14:17,781 - INFO - CodeInterpreter initialized successfully.
2024-02-02 18:14:17,786 - INFO - Session 20240202-141417-a5235e3f is initialized
2024-02-02 18:14:20,395 - INFO - Use back up engine: False
2024-02-02 18:14:46,739 - INFO - LLM output: {"response": [{"type": "init_plan", "content": "1. Import the list of Python files specified by the user\n2. Identify and print relevant variables of interest\n3. Identify and print relevant dataframe names and their columns\n4. Calculate the answer to the query\n5. Create an Excel file with detailed calculations and references\n6. Provide a detailed description of the calculation steps and assumptions\n7. Save the Excel file and print the full path"}, {"type": "plan", "content": "1. Import the list of Python files specified by the user\n2. Identify and print relevant variables of interest\n3. Identify and print relevant dataframe names and their columns\n4. Calculate the answer to the query\n5. Create an Excel file with detailed calculations and references\n6. Provide a detailed description of the calculation steps and assumptions\n7. Save the Excel file and print the full path"}, {"type": "current_plan_step", "content": "1. Import the list of Python files specified by the user"}, {"type": "send_to", "content": "CodeInterpreter"}, {"type": "message", "content": "# Import the list of Python files specified by the user\n# Since there are no files specified, we will proceed to the next steps."}]}
2024-02-02 18:14:46,746 - ERROR - Traceback (most recent call last):
  File "C:\Users\amantara\OneDrive - Microsoft\GBB\ADIA\PED\mm-doc-analysis-rag-ce\app\../Taskweaver\taskweaver\session\session.py", line 132, in send_message
    post = _send_message(post.send_to, post)
  File "C:\Users\amantara\OneDrive - Microsoft\GBB\ADIA\PED\mm-doc-analysis-rag-ce\app\../Taskweaver\taskweaver\session\session.py", line 104, in _send_message
    reply_post = self.planner.reply(
  File "C:\Users\amantara\OneDrive - Microsoft\GBB\ADIA\PED\mm-doc-analysis-rag-ce\app\../Taskweaver\taskweaver\planner\planner.py", line 222, in reply
    response_post = self.planner_post_translator.raw_text_to_post(
  File "C:\Users\amantara\OneDrive - Microsoft\GBB\ADIA\PED\mm-doc-analysis-rag-ce\app\../Taskweaver\taskweaver\role\translator.py", line 68, in raw_text_to_post
    event_handler(type_str, value)
TypeError: 'TWHandler' object is not callable

2024-02-02 18:22:20,900 - INFO - Planner initialized successfully
2024-02-02 18:22:20,983 - INFO - CodeInterpreter initialized successfully.
2024-02-02 18:22:20,986 - INFO - Session 20240202-142220-67015de1 is initialized
2024-02-02 18:22:21,641 - INFO - Use back up engine: False
2024-02-02 18:22:50,591 - INFO - LLM output: {"response": [{"type": "init_plan", "content": "1. Analyze the user's request and identify the variables of interest.\n2. Import the list of Python files specified by the user.\n3. Identify and print the relevant variables and their values.\n4. Identify and print the relevant dataframes and their columns.\n5. Extract information from the Python codeblocks if necessary.\n6. Generate the answer to the query, including all calculation steps.\n7. Provide a detailed description of the calculation steps.\n8. If numerical data is involved, create an Excel file with the data and calculation steps, save it, and print the full path."}, {"type": "plan", "content": "1. Import the list of Python files specified by the user.\n2. Identify and print the relevant variables and their values.\n3. Identify and print the relevant dataframes and their columns.\n4. Generate the answer to the query, including all calculation steps.\n5. Provide a detailed description of the calculation steps.\n6. If numerical data is involved, create an Excel file with the data and calculation steps, save it, and print the full path."}, {"type": "current_plan_step", "content": "1. Import the list of Python files specified by the user."}, {"type": "send_to", "content": "CodeInterpreter"}, {"type": "message", "content": "Please import the list of Python files specified by the user and confirm once done."}]}
2024-02-02 18:22:50,596 - ERROR - Traceback (most recent call last):
  File "C:\Users\amantara\OneDrive - Microsoft\GBB\ADIA\PED\mm-doc-analysis-rag-ce\app\../Taskweaver\taskweaver\session\session.py", line 132, in send_message
    post = _send_message(post.send_to, post)
  File "C:\Users\amantara\OneDrive - Microsoft\GBB\ADIA\PED\mm-doc-analysis-rag-ce\app\../Taskweaver\taskweaver\session\session.py", line 104, in _send_message
    reply_post = self.planner.reply(
  File "C:\Users\amantara\OneDrive - Microsoft\GBB\ADIA\PED\mm-doc-analysis-rag-ce\app\../Taskweaver\taskweaver\planner\planner.py", line 222, in reply
    response_post = self.planner_post_translator.raw_text_to_post(
  File "C:\Users\amantara\OneDrive - Microsoft\GBB\ADIA\PED\mm-doc-analysis-rag-ce\app\../Taskweaver\taskweaver\role\translator.py", line 68, in raw_text_to_post
    event_handler(type_str, value)
TypeError: 'TWHandler' object is not callable

